[2022-01-24 03:00:17,545] {taskinstance.py:1032} INFO - Dependencies all met for <TaskInstance: rides_dag.sql_connect_ manual__2022-01-24T02:54:11.103349+00:00 [queued]>
[2022-01-24 03:00:17,570] {taskinstance.py:1032} INFO - Dependencies all met for <TaskInstance: rides_dag.sql_connect_ manual__2022-01-24T02:54:11.103349+00:00 [queued]>
[2022-01-24 03:00:17,572] {taskinstance.py:1238} INFO - 
--------------------------------------------------------------------------------
[2022-01-24 03:00:17,574] {taskinstance.py:1239} INFO - Starting attempt 4 of 4
[2022-01-24 03:00:17,575] {taskinstance.py:1240} INFO - 
--------------------------------------------------------------------------------
[2022-01-24 03:00:17,599] {taskinstance.py:1259} INFO - Executing <Task(PythonOperator): sql_connect_> on 2022-01-24 02:54:11.103349+00:00
[2022-01-24 03:00:17,607] {standard_task_runner.py:52} INFO - Started process 365 to run task
[2022-01-24 03:00:17,613] {standard_task_runner.py:76} INFO - Running: ['***', 'tasks', 'run', 'rides_dag', 'sql_connect_', 'manual__2022-01-24T02:54:11.103349+00:00', '--job-id', '670', '--raw', '--subdir', 'DAGS_FOLDER/rides_dag.py', '--cfg-path', '/tmp/tmpbqxl1ans', '--error-file', '/tmp/tmpkcf_vmgm']
[2022-01-24 03:00:17,614] {standard_task_runner.py:77} INFO - Job 670: Subtask sql_connect_
[2022-01-24 03:00:17,704] {logging_mixin.py:109} INFO - Running <TaskInstance: rides_dag.sql_connect_ manual__2022-01-24T02:54:11.103349+00:00 [running]> on host ec724cd32110
[2022-01-24 03:00:17,788] {taskinstance.py:1426} INFO - Exporting the following env vars:
AIRFLOW_CTX_DAG_EMAIL=mcgaritym@gmail.com
AIRFLOW_CTX_DAG_OWNER=***
AIRFLOW_CTX_DAG_ID=rides_dag
AIRFLOW_CTX_TASK_ID=sql_connect_
AIRFLOW_CTX_EXECUTION_DATE=2022-01-24T02:54:11.103349+00:00
AIRFLOW_CTX_DAG_RUN_ID=manual__2022-01-24T02:54:11.103349+00:00
[2022-01-24 03:00:17,791] {logging_mixin.py:109} INFO - Current Working Directory:  /opt/***
[2022-01-24 03:00:17,792] {logging_mixin.py:109} INFO - Current Working Directory Files:  ['logs', 'dags', '***-worker.pid', '***.cfg', 'plugins', 'webserver_config.py']
[2022-01-24 03:00:17,793] {logging_mixin.py:109} INFO - Parent Directory:  /opt
[2022-01-24 03:00:17,794] {logging_mixin.py:109} INFO - Current Parent Directory Files:  ['***', 'microsoft', 'mssql-tools']
[2022-01-24 03:00:17,803] {taskinstance.py:1700} ERROR - Task failed with exception
Traceback (most recent call last):
  File "/home/airflow/.local/lib/python3.7/site-packages/mysql/connector/connection_cext.py", line 236, in _open_connection
    self._cmysql.connect(**cnx_kwargs)
_mysql_connector.MySQLInterfaceError: Can't connect to MySQL server on 'host.docker.internal:3308' (111)

During handling of the above exception, another exception occurred:

Traceback (most recent call last):
  File "/home/airflow/.local/lib/python3.7/site-packages/airflow/models/taskinstance.py", line 1329, in _run_raw_task
    self._execute_task_with_callbacks(context)
  File "/home/airflow/.local/lib/python3.7/site-packages/airflow/models/taskinstance.py", line 1455, in _execute_task_with_callbacks
    result = self._execute_task(context, self.task)
  File "/home/airflow/.local/lib/python3.7/site-packages/airflow/models/taskinstance.py", line 1511, in _execute_task
    result = execute_callable(context=context)
  File "/home/airflow/.local/lib/python3.7/site-packages/airflow/operators/python.py", line 174, in execute
    return_value = self.execute_callable()
  File "/home/airflow/.local/lib/python3.7/site-packages/airflow/operators/python.py", line 185, in execute_callable
    return self.python_callable(*self.op_args, **self.op_kwargs)
  File "/opt/airflow/dags/sql_connect.py", line 22, in sql_connect
    connection_1 = mysql.connector.connect(host=MYSQL_HOST, user=MYSQL_USER, password=MYSQL_ROOT_PASSWORD, port=MYSQL_PORT)
  File "/home/airflow/.local/lib/python3.7/site-packages/mysql/connector/__init__.py", line 272, in connect
    return CMySQLConnection(*args, **kwargs)
  File "/home/airflow/.local/lib/python3.7/site-packages/mysql/connector/connection_cext.py", line 85, in __init__
    self.connect(**kwargs)
  File "/home/airflow/.local/lib/python3.7/site-packages/mysql/connector/abstracts.py", line 1014, in connect
    self._open_connection()
  File "/home/airflow/.local/lib/python3.7/site-packages/mysql/connector/connection_cext.py", line 242, in _open_connection
    sqlstate=exc.sqlstate)
mysql.connector.errors.DatabaseError: 2003 (HY000): Can't connect to MySQL server on 'host.docker.internal:3308' (111)
[2022-01-24 03:00:17,825] {taskinstance.py:1277} INFO - Marking task as FAILED. dag_id=rides_dag, task_id=sql_connect_, execution_date=20220124T025411, start_date=20220124T030017, end_date=20220124T030017
[2022-01-24 03:00:17,850] {standard_task_runner.py:92} ERROR - Failed to execute job 670 for task sql_connect_
Traceback (most recent call last):
  File "/home/airflow/.local/lib/python3.7/site-packages/mysql/connector/connection_cext.py", line 236, in _open_connection
    self._cmysql.connect(**cnx_kwargs)
_mysql_connector.MySQLInterfaceError: Can't connect to MySQL server on 'host.docker.internal:3308' (111)

During handling of the above exception, another exception occurred:

Traceback (most recent call last):
  File "/home/airflow/.local/lib/python3.7/site-packages/airflow/task/task_runner/standard_task_runner.py", line 85, in _start_by_fork
    args.func(args, dag=self.dag)
  File "/home/airflow/.local/lib/python3.7/site-packages/airflow/cli/cli_parser.py", line 48, in command
    return func(*args, **kwargs)
  File "/home/airflow/.local/lib/python3.7/site-packages/airflow/utils/cli.py", line 92, in wrapper
    return f(*args, **kwargs)
  File "/home/airflow/.local/lib/python3.7/site-packages/airflow/cli/commands/task_command.py", line 298, in task_run
    _run_task_by_selected_method(args, dag, ti)
  File "/home/airflow/.local/lib/python3.7/site-packages/airflow/cli/commands/task_command.py", line 107, in _run_task_by_selected_method
    _run_raw_task(args, ti)
  File "/home/airflow/.local/lib/python3.7/site-packages/airflow/cli/commands/task_command.py", line 184, in _run_raw_task
    error_file=args.error_file,
  File "/home/airflow/.local/lib/python3.7/site-packages/airflow/utils/session.py", line 70, in wrapper
    return func(*args, session=session, **kwargs)
  File "/home/airflow/.local/lib/python3.7/site-packages/airflow/models/taskinstance.py", line 1329, in _run_raw_task
    self._execute_task_with_callbacks(context)
  File "/home/airflow/.local/lib/python3.7/site-packages/airflow/models/taskinstance.py", line 1455, in _execute_task_with_callbacks
    result = self._execute_task(context, self.task)
  File "/home/airflow/.local/lib/python3.7/site-packages/airflow/models/taskinstance.py", line 1511, in _execute_task
    result = execute_callable(context=context)
  File "/home/airflow/.local/lib/python3.7/site-packages/airflow/operators/python.py", line 174, in execute
    return_value = self.execute_callable()
  File "/home/airflow/.local/lib/python3.7/site-packages/airflow/operators/python.py", line 185, in execute_callable
    return self.python_callable(*self.op_args, **self.op_kwargs)
  File "/opt/airflow/dags/sql_connect.py", line 22, in sql_connect
    connection_1 = mysql.connector.connect(host=MYSQL_HOST, user=MYSQL_USER, password=MYSQL_ROOT_PASSWORD, port=MYSQL_PORT)
  File "/home/airflow/.local/lib/python3.7/site-packages/mysql/connector/__init__.py", line 272, in connect
    return CMySQLConnection(*args, **kwargs)
  File "/home/airflow/.local/lib/python3.7/site-packages/mysql/connector/connection_cext.py", line 85, in __init__
    self.connect(**kwargs)
  File "/home/airflow/.local/lib/python3.7/site-packages/mysql/connector/abstracts.py", line 1014, in connect
    self._open_connection()
  File "/home/airflow/.local/lib/python3.7/site-packages/mysql/connector/connection_cext.py", line 242, in _open_connection
    sqlstate=exc.sqlstate)
mysql.connector.errors.DatabaseError: 2003 (HY000): Can't connect to MySQL server on 'host.docker.internal:3308' (111)
[2022-01-24 03:00:17,907] {local_task_job.py:154} INFO - Task exited with return code 1
[2022-01-24 03:00:17,952] {local_task_job.py:264} INFO - 0 downstream tasks scheduled from follow-on schedule check
